<?xml version="1.0" ?>
<!-- =================================================================================== -->
<!-- |    This document was autogenerated by xacro from lbv150_uvms.urdf.xacro         | -->
<!-- |    EDITING THIS FILE BY HAND IS NOT RECOMMENDED                                 | -->
<!-- =================================================================================== -->
<robot name="lbv150_uvms" xmlns:xacro="http://www.ros.org/wiki/xacro">
  <!-- ros_control plugin
  <gazebo>
    <plugin name="gazebo_ros_control" filename="libgazebo_ros_control.so">
      <robotNamespace>/lbv150_uvms</robotNamespace>
    </plugin>
  </gazebo>
  -->
  <gazebo reference="base_link">
    <gravity>true</gravity>
    <selfCollide>true</selfCollide>
  </gazebo>
  <gazebo reference="arm_link1">
    <gravity>true</gravity>
    <selfCollide>true</selfCollide>
  </gazebo>
  <gazebo reference="arm_link2">
    <gravity>true</gravity>
    <selfCollide>false</selfCollide>
  </gazebo>
  <gazebo reference="arm_link3">
    <gravity>true</gravity>
    <selfCollide>true</selfCollide>
  </gazebo>
  <gazebo reference="arm_ee">
    <gravity>true</gravity>
    <selfCollide>true</selfCollide>
    <!--<material>Gazebo/Black</material>-->
  </gazebo>
  <gazebo>
    <plugin filename="libgazebo_ros_imu.so" name="imu_plugin1">
      <alwaysOn>true</alwaysOn>
      <bodyName>base_link</bodyName>
      <topicName>base_link/imu</topicName>
      <gaussianNoise>0.0</gaussianNoise>
      <updateRate>20.0</updateRate>
    </plugin>
  </gazebo>
  <material name="white">
    <color rgba="1 1 1 1"/>
  </material>
  <!--Vehicle-->
  <link name="base_link">
    <visual>
      <geometry>
        <mesh filename="package://csl_underwater_sim_gazebo/data/models/LBV150_karrasg.dae"/>
      </geometry>
      <origin rpy="0 0 0" xyz="0 0 0"/>
    </visual>
    <collision>
      <geometry>
        <box size="0.72 0.24 0.24"/>
      </geometry>
    </collision>
    <inertial>
      <origin rpy="0 0 0" xyz="0 0 0"/>
      <mass value="12"/>
      <inertia ixx="0.1589" ixy="0.0" ixz="0.0" iyy="0.1589" iyz="0.0" izz="0.1589"/>
    </inertial>
    <buoyancy>
      <compensation>1.0</compensation>
      <origin xyz="0 0 0"/>
      <limit radius=".5"/>
      <damping rpy="20 50 50" xyz="60 100 100"/>
    </buoyancy>
  </link>
  <!--Arm-->
  <link name="arm_link1">
    <visual>
      <geometry>
        <mesh filename="package://csl_underwater_sim_gazebo/data/models/LinkA.stl"/>
      </geometry>
      <origin rpy="0 0 3.14159" xyz="0.0 0.00 0"/>
      <material name="white"/>
    </visual>
    <inertial>
      <mass value="0.01"/>
      <inertia ixx="6.667e-7" ixy="0.0" ixz="0.0" iyy="6.667e-7" iyz="0.0" izz="6.667e-7"/>
    </inertial>
    <buoyancy>
      <compensation>1.0</compensation>
    </buoyancy>
  </link>
  <link name="arm_link2">
    <visual>
      <geometry>
        <mesh filename="package://csl_underwater_sim_gazebo/data/models/LinkB.stl"/>
      </geometry>
      <material name="white"/>
    </visual>
    <inertial>
      <mass value="0.01"/>
      <inertia ixx="6.667e-7" ixy="0.0" ixz="0.0" iyy="6.667e-7" iyz="0.0" izz="6.667e-7"/>
    </inertial>
    <buoyancy>
      <compensation>1.0</compensation>
    </buoyancy>
  </link>
  <link name="arm_link3">
    <visual>
      <geometry>
        <mesh filename="package://csl_underwater_sim_gazebo/data/models/LinkC.stl"/>
      </geometry>
      <origin rpy="-1.57 3.1459 0" xyz="-0.015 0.050 0"/>
      <material name="white"/>
    </visual>
    <inertial>
      <mass value="0.01"/>
      <inertia ixx="6.667e-7" ixy="0.0" ixz="0.0" iyy="6.667e-7" iyz="0.0" izz="6.667e-7"/>
    </inertial>
    <buoyancy>
      <compensation>1.0</compensation>
    </buoyancy>
  </link>
  <link name="arm_ee">
    <visual>
      <geometry>
        <cylinder length="0.10" radius="0.005"/>
      </geometry>
      <material name="white"/>
    </visual>
    <collision>
      <geometry>
        <box size="0.007 0.007 0.1"/>
      </geometry>
    </collision>
    <inertial>
      <mass value="0.01"/>
      <inertia ixx="6.667e-7" ixy="0.0" ixz="0.0" iyy="6.667e-7" iyz="0.0" izz="6.667e-7"/>
    </inertial>
    <buoyancy>
      <compensation>1.0</compensation>
    </buoyancy>
  </link>
  <!-- arm tool link -->
  <link name="arm_tool_link">
  </link>
  <joint name="arm_1_joint" type="revolute">
    <parent link="base_link"/>
    <child link="arm_link1"/>
    <axis xyz="0 0 1"/>
    <origin rpy="0 0 0" xyz="0.11 0 0.155"/>
    <limit effort="1000.0" lower="-3.14159265359" upper="3.14159265359" velocity="1.0"/>
  </joint>
  <joint name="arm_2_joint" type="revolute">
    <parent link="arm_link1"/>
    <child link="arm_link2"/>
    <axis xyz="0 0 1"/>
    <origin rpy="1.57 0 0" xyz="0 0 0.05"/>
    <limit effort="1000.0" lower="-1.57079632679" upper="1.1344640138" velocity="1.0"/>
  </joint>
  <joint name="arm_3_joint" type="revolute">
    <parent link="arm_link2"/>
    <child link="arm_link3"/>
    <axis xyz="0 0 1"/>
    <origin rpy="0 0 0" xyz="-0.0 0.147 0"/>
    <limit effort="1000.0" lower="-2.26892802759" upper="1.57079632679" velocity="1.0"/>
  </joint>
  <joint name="arm_4_joint" type="revolute">
    <parent link="arm_link3"/>
    <child link="arm_tool_link"/>
    <axis xyz="0 0 1"/>
    <origin rpy="-1.57 0 0" xyz="-0.015 0.07 0"/>
    <limit effort="1000.0" lower="-3.14159265359" upper="3.14159265359" velocity="1.0"/>
  </joint>
  <joint name="arm_fixed" type="fixed">
    <parent link="arm_tool_link"/>
    <child link="arm_ee"/>
    <origin rpy="0.0 0 0" xyz="0.0 0.0 0"/>
  </joint>
</robot>

