<sdf version='1.4'>
  <world name='default'>
    <light name='sun' type='directional'>
      <cast_shadows>1</cast_shadows>
      <pose>0 0 10 0 -0 0</pose>
      <diffuse>0.8 0.8 0.8 1</diffuse>
      <specular>0.2 0.2 0.2 1</specular>
      <attenuation>
        <range>1000</range>
        <constant>0.9</constant>
        <linear>0.01</linear>
        <quadratic>0.001</quadratic>
      </attenuation>
      <direction>-0.5 0.1 -0.9</direction>
    </light>
    <physics type='ode'>
      <max_step_size>0.001</max_step_size>
      <real_time_factor>1</real_time_factor>
      <real_time_update_rate>1000</real_time_update_rate>
      <gravity>0 0 -9.8</gravity>
    </physics>
    <scene>
      <ambient>0.4 0.4 0.4 1</ambient>
      <background>0.7 0.7 0.7 1</background>
      <shadows>1</shadows>
    </scene>
    <spherical_coordinates>
      <surface_model>EARTH_WGS84</surface_model>
      <latitude_deg>0</latitude_deg>
      <longitude_deg>0</longitude_deg>
      <elevation>0</elevation>
      <heading_deg>0</heading_deg>
    </spherical_coordinates>
    <state world_name='default'>
      <sim_time>221 931000000</sim_time>
      <real_time>136 749679257</real_time>
      <wall_time>1510257570 919230035</wall_time>
      <model name='lbv150_uvms'>
        <pose>6.63022 1.84483 -25114.6 -0.246737 -1.46478 -2.79534</pose>
        <link name='arm_link1'>
          <pose>6.77271 1.85599 -25114.5 -1.14678 -1.31873 -1.88472</pose>
          <velocity>0.148956 0.040973 -701.684 0.046872 0.597498 0.050064</velocity>
          <acceleration>0 0 0 0 -0 0</acceleration>
          <wrench>0 0 0 0 -0 0</wrench>
        </link>
        <link name='arm_link2'>
          <pose>6.82221 1.86087 -25114.5 1.32879 -0.32119 -2.94238</pose>
          <velocity>0.151786 0.043209 -701.713 0.066561 0.436236 0.012137</velocity>
          <acceleration>0 0 0 0 -0 0</acceleration>
          <wrench>0 0 0 0 -0 0</wrench>
        </link>
        <link name='arm_link3'>
          <pose>6.87334 1.83525 -25114.4 1.2527 -0.756754 -2.79781</pose>
          <velocity>0.211177 0.034815 -701.737 0.064609 0.452226 0.015898</velocity>
          <acceleration>0 0 0 0 -0 0</acceleration>
          <wrench>0 0 0 0 -0 0</wrench>
        </link>
        <link name='arm_tool_link'>
          <pose>6.93397 1.8337 -25114.3 0.785431 -0.215192 1.67879</pose>
          <velocity>0.228412 0.03332 -701.765 0.71732 0.385176 0.643021</velocity>
          <acceleration>0 0 0 0 -0 0</acceleration>
          <wrench>0 0 0 0 -0 0</wrench>
        </link>
        <link name='base_link'>
          <pose>6.63022 1.84483 -25114.6 -0.246737 -1.46478 -2.79534</pose>
          <velocity>0.076357 0.022649 -701.6 -0.107544 0.582291 0.034012</velocity>
          <acceleration>0 0 0 0 -0 0</acceleration>
          <wrench>0 0 0 0 -0 0</wrench>
        </link>
      </model>
    </state>
    <gui fullscreen='0'>
      <camera name='user_camera'>
        <pose>6.94967 -6.61102 2.41898 0 0.275643 2.35619</pose>
        <view_controller>orbit</view_controller>
      </camera>
    </gui>
    <model name='lbv150_uvms'>
      <link name='base_link'>
        <pose>0 0 0 0 -0 0</pose>
        <inertial>
          <pose>0 0 0 0 -0 0</pose>
          <mass>12</mass>
          <inertia>
            <ixx>0.1589</ixx>
            <ixy>0</ixy>
            <ixz>0</ixz>
            <iyy>0.1589</iyy>
            <iyz>0</iyz>
            <izz>0.1589</izz>
          </inertia>
        </inertial>
        <collision name='base_link_collision'>
          <pose>0 0 0 0 -0 0</pose>
          <geometry>
            <box>
              <size>0.72 0.24 0.24</size>
            </box>
          </geometry>
          <surface>
            <contact>
              <ode/>
            </contact>
            <friction>
              <ode/>
            </friction>
            <bounce/>
          </surface>
          <max_contacts>10</max_contacts>
        </collision>
        <visual name='base_link_visual'>
          <pose>0 0 0 0 -0 0</pose>
          <geometry>
            <mesh>
              <scale>1 1 1</scale>
              <uri>/home/karrasg/catkin_ws/src/csl_underwater_sim_gazebo/data/models/LBV150_karrasg.dae</uri>
            </mesh>
          </geometry>
        </visual>
        <gravity>1</gravity>
        <velocity_decay>
          <linear>0</linear>
          <angular>0</angular>
        </velocity_decay>
        <self_collide>1</self_collide>
        <gravity>1</gravity>
        <kinematic>0</kinematic>
      </link>
      <link name='arm_link1'>
        <pose>0.11 0 0.155 0 -0 0</pose>
        <inertial>
          <pose>0 0 0 0 -0 0</pose>
          <mass>0.01</mass>
          <inertia>
            <ixx>6.667e-07</ixx>
            <ixy>0</ixy>
            <ixz>0</ixz>
            <iyy>6.667e-07</iyy>
            <iyz>0</iyz>
            <izz>6.667e-07</izz>
          </inertia>
        </inertial>
        <visual name='arm_link1_visual'>
          <pose>0 0 0 0 -0 3.14159</pose>
          <geometry>
            <mesh>
              <scale>1 1 1</scale>
              <uri>/home/karrasg/catkin_ws/src/csl_underwater_sim_gazebo/data/models/LinkA.stl</uri>
            </mesh>
          </geometry>
        </visual>
        <gravity>1</gravity>
        <velocity_decay>
          <linear>0</linear>
          <angular>0</angular>
        </velocity_decay>
        <self_collide>1</self_collide>
        <gravity>1</gravity>
        <kinematic>0</kinematic>
      </link>
      <joint name='arm_1_joint' type='revolute'>
        <child>arm_link1</child>
        <parent>base_link</parent>
        <axis>
          <xyz>0 0 1</xyz>
          <limit>
            <lower>-3.14159</lower>
            <upper>3.14159</upper>
            <effort>1000</effort>
            <velocity>1</velocity>
          </limit>
          <dynamics/>
        </axis>
      </joint>
      <link name='arm_link2'>
        <pose>0.11 0 0.205 1.57 -0 0</pose>
        <inertial>
          <pose>0 0 0 0 -0 0</pose>
          <mass>0.01</mass>
          <inertia>
            <ixx>6.667e-07</ixx>
            <ixy>0</ixy>
            <ixz>0</ixz>
            <iyy>6.667e-07</iyy>
            <iyz>0</iyz>
            <izz>6.667e-07</izz>
          </inertia>
        </inertial>
        <visual name='arm_link2_visual'>
          <pose>0 0 0 0 -0 0</pose>
          <geometry>
            <mesh>
              <scale>1 1 1</scale>
              <uri>/home/karrasg/catkin_ws/src/csl_underwater_sim_gazebo/data/models/LinkB.stl</uri>
            </mesh>
          </geometry>
        </visual>
        <gravity>1</gravity>
        <velocity_decay>
          <linear>0</linear>
          <angular>0</angular>
        </velocity_decay>
        <self_collide>1</self_collide>
        <gravity>1</gravity>
        <kinematic>0</kinematic>
      </link>
      <joint name='arm_2_joint' type='revolute'>
        <child>arm_link2</child>
        <parent>arm_link1</parent>
        <axis>
          <xyz>0 -1 0.000796</xyz>
          <limit>
            <lower>-1.5708</lower>
            <upper>1.13446</upper>
            <effort>1000</effort>
            <velocity>1</velocity>
          </limit>
          <dynamics/>
        </axis>
      </joint>
      <link name='arm_link3'>
        <pose>0.11 0.00011706 0.352 1.57 -0 0</pose>
        <inertial>
          <pose>0 0 0 0 -0 0</pose>
          <mass>0.01</mass>
          <inertia>
            <ixx>6.667e-07</ixx>
            <ixy>0</ixy>
            <ixz>0</ixz>
            <iyy>6.667e-07</iyy>
            <iyz>0</iyz>
            <izz>6.667e-07</izz>
          </inertia>
        </inertial>
        <visual name='arm_link3_visual'>
          <pose>-0.015 0.05 0 1.57159 -0.00430735 -3.14159</pose>
          <geometry>
            <mesh>
              <scale>1 1 1</scale>
              <uri>/home/karrasg/catkin_ws/src/csl_underwater_sim_gazebo/data/models/LinkC.stl</uri>
            </mesh>
          </geometry>
        </visual>
        <gravity>1</gravity>
        <velocity_decay>
          <linear>0</linear>
          <angular>0</angular>
        </velocity_decay>
        <self_collide>1</self_collide>
        <gravity>1</gravity>
        <kinematic>0</kinematic>
      </link>
      <joint name='arm_3_joint' type='revolute'>
        <child>arm_link3</child>
        <parent>arm_link2</parent>
        <axis>
          <xyz>0 -1 0.000796</xyz>
          <limit>
            <lower>-2.26893</lower>
            <upper>1.5708</upper>
            <effort>1000</effort>
            <velocity>1</velocity>
          </limit>
          <dynamics/>
        </axis>
      </joint>
      <link name='arm_tool_link'>
        <pose>0.095 0.000172803 0.422 0 -0 0</pose>
        <inertial>
          <pose>0 0 0 0 -0 0</pose>
          <mass>0.01</mass>
          <inertia>
            <ixx>6.667e-07</ixx>
            <ixy>0</ixy>
            <ixz>0</ixz>
            <iyy>6.667e-07</iyy>
            <iyz>0</iyz>
            <izz>6.667e-07</izz>
          </inertia>
        </inertial>
        <collision name='arm_tool_link_collision_arm_ee'>
          <pose>0 0 0 0 -0 0</pose>
          <geometry>
            <box>
              <size>0.007 0.007 0.1</size>
            </box>
          </geometry>
          <surface>
            <contact>
              <ode/>
            </contact>
            <friction>
              <ode/>
            </friction>
            <bounce/>
          </surface>
          <max_contacts>10</max_contacts>
        </collision>
        <visual name='arm_tool_link_visual_arm_ee'>
          <pose>0 0 0 0 -0 0</pose>
          <geometry>
            <cylinder>
              <length>0.1</length>
              <radius>0.005</radius>
            </cylinder>
          </geometry>
        </visual>
        <gravity>1</gravity>
        <velocity_decay>
          <linear>0</linear>
          <angular>0</angular>
        </velocity_decay>
        <self_collide>1</self_collide>
        <gravity>1</gravity>
        <kinematic>0</kinematic>
      </link>
      <joint name='arm_4_joint' type='revolute'>
        <child>arm_tool_link</child>
        <parent>arm_link3</parent>
        <axis>
          <xyz>0 0 1</xyz>
          <limit>
            <lower>-3.14159</lower>
            <upper>3.14159</upper>
            <effort>1000</effort>
            <velocity>1</velocity>
          </limit>
          <dynamics/>
        </axis>
      </joint>
      <plugin name='gazebo_ros_control' filename='libgazebo_ros_control.so'>
        <robotNamespace>/lbv150_uvms</robotNamespace>
      </plugin>
      <plugin name='imu_plugin1' filename='libgazebo_ros_imu.so'>
        <alwaysOn>true</alwaysOn>
        <bodyName>base_link</bodyName>
        <topicName>base_link/imu</topicName>
        <gaussianNoise>0.0</gaussianNoise>
        <updateRate>20.0</updateRate>
        <robotNamespace>/</robotNamespace>
      </plugin>
      <static>0</static>
      <plugin name='freefloating_gazebo_control' filename='libfreefloating_gazebo_control.so'>
        <link/>
        <buoyancy>
          <compensation>1.01</compensation>
          <origin/>
          <limit/>
          <damping/>
        </buoyancy>
        <robotNamespace>/</robotNamespace>
      </plugin>
      <pose>0 0 1.5 3.14159 -0 0</pose>
    </model>
  </world>
</sdf>
